Workbook

Sheet Pre-Season Load
B1: Target Match Load | H1: Weekly Progressions
A2: Position | B2: TD | C2: HMLD | D2: HSR | E2: A+D | F2: BIP m/min | H2: Week 1 | I2: Week 2 | J2: Week 3 | K2: Week 4 | L2: Week 5 | M2: Week 6
A3: Prop | B3: 5626 | C3: 391 | D3: 100 | E3: 31 | F3: 85 | H3: 1.8 | I3: 2.2 | J3: 2.6 | K3: 2.4 | L3: 2.5 | M3: 2.6
A4: Hooker | B4: 5487 | C4: 364 | D4: 140 | E4: 30 | F4: 81 | H4: TD | I4: HMLD | J4: HSR | K4: A+D | L4: TOF | M4: BIP
A5: Lock | B5: 6309 | C5: 563 | D5: 284 | E5: 53 | F5: 103 | G5: Week 1 AVG | H5: =AVERAGE(B14:B22) -> 11526.6 | I5: =AVERAGE(C14:C22) -> 1466.2 | J5: =AVERAGE(D14:D22) -> 908.2 | K5: =AVERAGE(E14:E22) -> 137 | L5: 260 | M5: 26
A6: Back row | B6: 6399 | C6: 698 | D6: 356 | E6: 71 | F6: 106 | G6: Week 2 AVG | H6: =AVERAGE(B26:B34) -> 14088.067 | I6: =AVERAGE(C26:C34) -> 1792.0222 | J6: =AVERAGE(D26:D34) -> 1110.0222 | K6: =AVERAGE(E26:E34) -> 167.44444 | L6: 275 | M6: 34
A7: Scrum-half | B7: 6484 | C7: 1193 | D7: 819 | E7: 102 | F7: 106 | G7: Week 3 AVG | H7: =AVERAGE(B38:B46) -> 16649.533 | I7: =AVERAGE(C38:C46) -> 2117.8444 | J7: =AVERAGE(D38:D46) -> 1311.8444 | K7: =AVERAGE(E38:E46) -> 197.88889 | L7: 295 | M7: 44
A8: Fly-half | B8: 6056 | C8: 661 | D8: 269 | E8: 87 | F8: 95 | G8: Week 4 AVG | H8: =AVERAGE(B50:B58) -> 15368.8 | I8: =AVERAGE(C50:C58) -> 1954.9333 | J8: =AVERAGE(D50:D58) -> 1210.9333 | K8: =AVERAGE(E50:E58) -> 182.66667 | L8: 270 | M8: 40
A9: Center | B9: 6757 | C9: 1075 | D9: 733 | E9: 113 | F9: 112 | G9: Week 5 AVG | H9: =AVERAGE(B62:B70) -> 16009.167 | I9: =AVERAGE(C62:C70) -> 2036.3889 | J9: =AVERAGE(D62:D70) -> 1261.3889 | K9: =AVERAGE(E62:E70) -> 190.27778 | L9: 305 | M9: 54
A10: Wing | B10: 7385 | C10: 1291 | D10: 1034 | E10: 105 | F10: 130 | G10: Week 6 AVG | H10: =AVERAGE(B74:B82) -> 16649.533 | I10: =AVERAGE(C74:C82) -> 2117.8444 | J10: =AVERAGE(D74:D82) -> 1311.8444 | K10: =AVERAGE(E74:E82) -> 197.88889 | L10: 315 | M10: 18
A11: Fullback | B11: 7130 | C11: 1095 | D11: 806 | E11: 93 | F11: 121 | H11: 0.1 | I11: 0.1 | J11: 0.1 | K11: 0.05 | M11: 0.35 | N11: 0.35 | O11: 0.5 | P11: 0.3 | R11: 0.4 | S11: 0.45 | T11: 0.35 | U11: 0.5 | W11: 0.15 | X11: 0.1 | Y11: 0.05 | Z11: 0.15 | AB11: Week 1 TOF
A12: Week 1 | H12: Monday - Speed Testing | M12: Tuesday - Bronco Testing | R12: Thursday - Shuttle Testing | W12: Friday - Skills | AB12: Mon | AC12: 60
A13: Position | B13: TD | C13: HMLD | D13: HSR | E13: A+D | F13: BIP m/min | H13: TD | I13: HMLD | J13: HSR | K13: A+D | M13: TD | N13: HMLD | O13: HSR | P13: A+D | R13: TD | S13: HMLD | T13: HSR | U13: A+D | W13: TD | X13: HMLD | Y13: HSR | Z13: A+D | AB13: Tue | AC13: 70
A14: Prop | B14: =B3*$H$3 -> 10126.8 | C14: =C3*$H$3 -> 703.8 | D14: =D3*$H$3 -> 180 | E14: =E3*$H$3 -> 55.8 | F14: 85 | H14: =B14*$H$11 -> 1012.68 | I14: =C14*$I$11 -> 70.38 | J14: =D14*$J$11 -> 18 | K14: =E14*$K$11 -> 2.79 | M14: =B14*$M$11 -> 3544.38 | N14: =C14*$N$11 -> 246.33 | O14: =D14*$O$11 -> 90 | P14: =E14*$P$11 -> 16.74 | R14: =B14*$R$11 -> 4050.72 | S14: =C14*$S$11 -> 316.71 | T14: =D14*$T$11 -> 63 | U14: =E14*$U$11 -> 27.9 | W14: =B14*$W$11 -> 1519.02 | X14: =C14*$X$11 -> 70.38 | Y14: =D14*$Y$11 -> 9 | Z14: =E14*$Z$11 -> 8.37 | AB14: Thu | AC14: 70
A15: Hooker | B15: =B4*$H$3 -> 9876.6 | C15: =C4*$H$3 -> 655.2 | D15: =D4*$H$3 -> 252 | E15: =E4*$H$3 -> 54 | F15: 81 | H15: =B15*$H$11 -> 987.66 | I15: =C15*$I$11 -> 65.52 | J15: =D15*$J$11 -> 25.2 | K15: =E15*$K$11 -> 2.7 | M15: =B15*$M$11 -> 3456.81 | N15: =C15*$N$11 -> 229.32 | O15: =D15*$O$11 -> 126 | P15: =E15*$P$11 -> 16.2 | R15: =B15*$R$11 -> 3950.64 | S15: =C15*$S$11 -> 294.84 | T15: =D15*$T$11 -> 88.2 | U15: =E15*$U$11 -> 27 | W15: =B15*$W$11 -> 1481.49 | X15: =C15*$X$11 -> 65.52 | Y15: =D15*$Y$11 -> 12.6 | Z15: =E15*$Z$11 -> 8.1 | AB15: Fri | AC15: 60
A16: Lock | B16: =B5*$H$3 -> 11356.2 | C16: =C5*$H$3 -> 1013.4 | D16: =D5*$H$3 -> 511.2 | E16: =E5*$H$3 -> 95.4 | F16: 103 | H16: =B16*$H$11 -> 1135.62 | I16: =C16*$I$11 -> 101.34 | J16: =D16*$J$11 -> 51.12 | K16: =E16*$K$11 -> 4.77 | M16: =B16*$M$11 -> 3974.67 | N16: =C16*$N$11 -> 354.69 | O16: =D16*$O$11 -> 255.6 | P16: =E16*$P$11 -> 28.62 | R16: =B16*$R$11 -> 4542.48 | S16: =C16*$S$11 -> 456.03 | T16: =D16*$T$11 -> 178.92 | U16: =E16*$U$11 -> 47.7 | W16: =B16*$W$11 -> 1703.43 | X16: =C16*$X$11 -> 101.34 | Y16: =D16*$Y$11 -> 25.56 | Z16: =E16*$Z$11 -> 14.31 | AC16: =SUM(AC12:AC15) -> 260
A17: Back row | B17: =B6*$H$3 -> 11518.2 | C17: =C6*$H$3 -> 1256.4 | D17: =D6*$H$3 -> 640.8 | E17: =E6*$H$3 -> 127.8 | F17: 106 | H17: =B17*$H$11 -> 1151.82 | I17: =C17*$I$11 -> 125.64 | J17: =D17*$J$11 -> 64.08 | K17: =E17*$K$11 -> 6.39 | M17: =B17*$M$11 -> 4031.37 | N17: =C17*$N$11 -> 439.74 | O17: =D17*$O$11 -> 320.4 | P17: =E17*$P$11 -> 38.34 | R17: =B17*$R$11 -> 4607.28 | S17: =C17*$S$11 -> 565.38 | T17: =D17*$T$11 -> 224.28 | U17: =E17*$U$11 -> 63.9 | W17: =B17*$W$11 -> 1727.73 | X17: =C17*$X$11 -> 125.64 | Y17: =D17*$Y$11 -> 32.04 | Z17: =E17*$Z$11 -> 19.17 | AB17: Week 2 TOF
A18: Scrum-half | B18: =B7*$H$3 -> 11671.2 | C18: =C7*$H$3 -> 2147.4 | D18: =D7*$H$3 -> 1474.2 | E18: =E7*$H$3 -> 183.6 | F18: 106 | H18: =B18*$H$11 -> 1167.12 | I18: =C18*$I$11 -> 214.74 | J18: =D18*$J$11 -> 147.42 | K18: =E18*$K$11 -> 9.18 | M18: =B18*$M$11 -> 4084.92 | N18: =C18*$N$11 -> 751.59 | O18: =D18*$O$11 -> 737.1 | P18: =E18*$P$11 -> 55.08 | R18: =B18*$R$11 -> 4668.48 | S18: =C18*$S$11 -> 966.33 | T18: =D18*$T$11 -> 515.97 | U18: =E18*$U$11 -> 91.8 | W18: =B18*$W$11 -> 1750.68 | X18: =C18*$X$11 -> 214.74 | Y18: =D18*$Y$11 -> 73.71 | Z18: =E18*$Z$11 -> 27.54 | AB18: Mon | AC18: 60
A19: Fly-half | B19: =B8*$H$3 -> 10900.8 | C19: =C8*$H$3 -> 1189.8 | D19: =D8*$H$3 -> 484.2 | E19: =E8*$H$3 -> 156.6 | F19: 95 | H19: =B19*$H$11 -> 1090.08 | I19: =C19*$I$11 -> 118.98 | J19: =D19*$J$11 -> 48.42 | K19: =E19*$K$11 -> 7.83 | M19: =B19*$M$11 -> 3815.28 | N19: =C19*$N$11 -> 416.43 | O19: =D19*$O$11 -> 242.1 | P19: =E19*$P$11 -> 46.98 | R19: =B19*$R$11 -> 4360.32 | S19: =C19*$S$11 -> 535.41 | T19: =D19*$T$11 -> 169.47 | U19: =E19*$U$11 -> 78.3 | W19: =B19*$W$11 -> 1635.12 | X19: =C19*$X$11 -> 118.98 | Y19: =D19*$Y$11 -> 24.21 | Z19: =E19*$Z$11 -> 23.49 | AB19: Tue | AC19: 75
A20: Center | B20: =B9*$H$3 -> 12162.6 | C20: =C9*$H$3 -> 1935 | D20: =D9*$H$3 -> 1319.4 | E20: =E9*$H$3 -> 203.4 | F20: 112 | H20: =B20*$H$11 -> 1216.26 | I20: =C20*$I$11 -> 193.5 | J20: =D20*$J$11 -> 131.94 | K20: =E20*$K$11 -> 10.17 | M20: =B20*$M$11 -> 4256.91 | N20: =C20*$N$11 -> 677.25 | O20: =D20*$O$11 -> 659.7 | P20: =E20*$P$11 -> 61.02 | R20: =B20*$R$11 -> 4865.04 | S20: =C20*$S$11 -> 870.75 | T20: =D20*$T$11 -> 461.79 | U20: =E20*$U$11 -> 101.7 | W20: =B20*$W$11 -> 1824.39 | X20: =C20*$X$11 -> 193.5 | Y20: =D20*$Y$11 -> 65.97 | Z20: =E20*$Z$11 -> 30.51 | AB20: Thu | AC20: 80
A21: Wing | B21: =B10*$H$3 -> 13293 | C21: =C10*$H$3 -> 2323.8 | D21: =D10*$H$3 -> 1861.2 | E21: =E10*$H$3 -> 189 | F21: 130 | H21: =B21*$H$11 -> 1329.3 | I21: =C21*$I$11 -> 232.38 | J21: =D21*$J$11 -> 186.12 | K21: =E21*$K$11 -> 9.45 | M21: =B21*$M$11 -> 4652.55 | N21: =C21*$N$11 -> 813.33 | O21: =D21*$O$11 -> 930.6 | P21: =E21*$P$11 -> 56.7 | R21: =B21*$R$11 -> 5317.2 | S21: =C21*$S$11 -> 1045.71 | T21: =D21*$T$11 -> 651.42 | U21: =E21*$U$11 -> 94.5 | W21: =B21*$W$11 -> 1993.95 | X21: =C21*$X$11 -> 232.38 | Y21: =D21*$Y$11 -> 93.06 | Z21: =E21*$Z$11 -> 28.35 | AB21: Fri | AC21: 60
A22: Fullback | B22: =B11*$H$3 -> 12834 | C22: =C11*$H$3 -> 1971 | D22: =D11*$H$3 -> 1450.8 | E22: =E11*$H$3 -> 167.4 | F22: 121 | H22: =B22*$H$11 -> 1283.4 | I22: =C22*$I$11 -> 197.1 | J22: =D22*$J$11 -> 145.08 | K22: =E22*$K$11 -> 8.37 | M22: =B22*$M$11 -> 4491.9 | N22: =C22*$N$11 -> 689.85 | O22: =D22*$O$11 -> 725.4 | P22: =E22*$P$11 -> 50.22 | R22: =B22*$R$11 -> 5133.6 | S22: =C22*$S$11 -> 886.95 | T22: =D22*$T$11 -> 507.78 | U22: =E22*$U$11 -> 83.7 | W22: =B22*$W$11 -> 1925.1 | X22: =C22*$X$11 -> 197.1 | Y22: =D22*$Y$11 -> 72.54 | Z22: =E22*$Z$11 -> 25.11 | AC22: =SUM(AC18:AC21) -> 275
H23: 0.15 | I23: 0.1 | J23: 0.1 | K23: 0.1 | M23: 0.35 | N23: 0.35 | O23: 0.5 | P23: 0.3 | R23: 0.4 | S23: 0.45 | T23: 0.35 | U23: 0.5 | W23: 0.1 | X23: 0.1 | Y23: 0.05 | Z23: 0.1 | AB23: Week 3 TOF
A24: Week 2 | H24: Monday - Skills | M24: Tuesday - Team | R24: Thursday - Team | W24: Friday - Skills | AB24: Mon | AC24: 60
A25: Position | B25: TD | C25: HMLD | D25: HSR | E25: A+D | F25: BIP m/min | H25: TD | I25: HMLD | J25: HSR | K25: A+D | M25: TD | N25: HMLD | O25: HSR | P25: A+D | R25: TD | S25: HMLD | T25: HSR | U25: A+D | W25: TD | X25: HMLD | Y25: HSR | Z25: A+D | AB25: Tue | AC25: 80
A26: Prop | B26: =B3*$I$3 -> 12377.2 | C26: =C3*$I$3 -> 860.2 | D26: =D3*$I$3 -> 220 | E26: =E3*$I$3 -> 68.2 | F26: 85 | H26: =B26*$H$23 -> 1856.58 | I26: =C26*$I$23 -> 86.02 | J26: =D26*$J$23 -> 22 | K26: =E26*$K$23 -> 6.82 | M26: =B26*$M$23 -> 4332.02 | N26: =C26*$N$23 -> 301.07 | O26: =D26*$O$23 -> 110 | P26: =E26*$P$23 -> 20.46 | R26: =B26*$R$23 -> 4950.88 | S26: =C26*$S$23 -> 387.09 | T26: =D26*$T$23 -> 77 | U26: =E26*$U$23 -> 34.1 | W26: =B26*$W$23 -> 1237.72 | X26: =C26*$X$23 -> 86.02 | Y26: =D26*$Y$23 -> 11 | Z26: =E26*$Z$23 -> 6.82 | AB26: Thu | AC26: 85
A27: Hooker | B27: =B4*$I$3 -> 12071.4 | C27: =C4*$I$3 -> 800.8 | D27: =D4*$I$3 -> 308 | E27: =E4*$I$3 -> 66 | F27: 81 | H27: =B27*$H$23 -> 1810.71 | I27: =C27*$I$23 -> 80.08 | J27: =D27*$J$23 -> 30.8 | K27: =E27*$K$23 -> 6.6 | M27: =B27*$M$23 -> 4224.99 | N27: =C27*$N$23 -> 280.28 | O27: =D27*$O$23 -> 154 | P27: =E27*$P$23 -> 19.8 | R27: =B27*$R$23 -> 4828.56 | S27: =C27*$S$23 -> 360.36 | T27: =D27*$T$23 -> 107.8 | U27: =E27*$U$23 -> 33 | W27: =B27*$W$23 -> 1207.14 | X27: =C27*$X$23 -> 80.08 | Y27: =D27*$Y$23 -> 15.4 | Z27: =E27*$Z$23 -> 6.6 | AB27: Sat | AC27: 70
A28: Lock | B28: =B5*$I$3 -> 13879.8 | C28: =C5*$I$3 -> 1238.6 | D28: =D5*$I$3 -> 624.8 | E28: =E5*$I$3 -> 116.6 | F28: 103 | H28: =B28*$H$23 -> 2081.97 | I28: =C28*$I$23 -> 123.86 | J28: =D28*$J$23 -> 62.48 | K28: =E28*$K$23 -> 11.66 | M28: =B28*$M$23 -> 4857.93 | N28: =C28*$N$23 -> 433.51 | O28: =D28*$O$23 -> 312.4 | P28: =E28*$P$23 -> 34.98 | R28: =B28*$R$23 -> 5551.92 | S28: =C28*$S$23 -> 557.37 | T28: =D28*$T$23 -> 218.68 | U28: =E28*$U$23 -> 58.3 | W28: =B28*$W$23 -> 1387.98 | X28: =C28*$X$23 -> 123.86 | Y28: =D28*$Y$23 -> 31.24 | Z28: =E28*$Z$23 -> 11.66 | AC28: =SUM(AC24:AC27) -> 295
A29: Back row | B29: =B6*$I$3 -> 14077.8 | C29: =C6*$I$3 -> 1535.6 | D29: =D6*$I$3 -> 783.2 | E29: =E6*$I$3 -> 156.2 | F29: 106 | H29: =B29*$H$23 -> 2111.67 | I29: =C29*$I$23 -> 153.56 | J29: =D29*$J$23 -> 78.32 | K29: =E29*$K$23 -> 15.62 | M29: =B29*$M$23 -> 4927.23 | N29: =C29*$N$23 -> 537.46 | O29: =D29*$O$23 -> 391.6 | P29: =E29*$P$23 -> 46.86 | R29: =B29*$R$23 -> 5631.12 | S29: =C29*$S$23 -> 691.02 | T29: =D29*$T$23 -> 274.12 | U29: =E29*$U$23 -> 78.1 | W29: =B29*$W$23 -> 1407.78 | X29: =C29*$X$23 -> 153.56 | Y29: =D29*$Y$23 -> 39.16 | Z29: =E29*$Z$23 -> 15.62 | AB29: Week 4 TOF
A30: Scrum-half | B30: =B7*$I$3 -> 14264.8 | C30: =C7*$I$3 -> 2624.6 | D30: =D7*$I$3 -> 1801.8 | E30: =E7*$I$3 -> 224.4 | F30: 106 | H30: =B30*$H$23 -> 2139.72 | I30: =C30*$I$23 -> 262.46 | J30: =D30*$J$23 -> 180.18 | K30: =E30*$K$23 -> 22.44 | M30: =B30*$M$23 -> 4992.68 | N30: =C30*$N$23 -> 918.61 | O30: =D30*$O$23 -> 900.9 | P30: =E30*$P$23 -> 67.32 | R30: =B30*$R$23 -> 5705.92 | S30: =C30*$S$23 -> 1181.07 | T30: =D30*$T$23 -> 630.63 | U30: =E30*$U$23 -> 112.2 | W30: =B30*$W$23 -> 1426.48 | X30: =C30*$X$23 -> 262.46 | Y30: =D30*$Y$23 -> 90.09 | Z30: =E30*$Z$23 -> 22.44 | AB30: Mon | AC30: 45
A31: Fly-half | B31: =B8*$I$3 -> 13323.2 | C31: =C8*$I$3 -> 1454.2 | D31: =D8*$I$3 -> 591.8 | E31: =E8*$I$3 -> 191.4 | F31: 95 | H31: =B31*$H$23 -> 1998.48 | I31: =C31*$I$23 -> 145.42 | J31: =D31*$J$23 -> 59.18 | K31: =E31*$K$23 -> 19.14 | M31: =B31*$M$23 -> 4663.12 | N31: =C31*$N$23 -> 508.97 | O31: =D31*$O$23 -> 295.9 | P31: =E31*$P$23 -> 57.42 | R31: =B31*$R$23 -> 5329.28 | S31: =C31*$S$23 -> 654.39 | T31: =D31*$T$23 -> 207.13 | U31: =E31*$U$23 -> 95.7 | W31: =B31*$W$23 -> 1332.32 | X31: =C31*$X$23 -> 145.42 | Y31: =D31*$Y$23 -> 29.59 | Z31: =E31*$Z$23 -> 19.14 | AB31: Tue | AC31: 80
A32: Center | B32: =B9*$I$3 -> 14865.4 | C32: =C9*$I$3 -> 2365 | D32: =D9*$I$3 -> 1612.6 | E32: =E9*$I$3 -> 248.6 | F32: 112 | H32: =B32*$H$23 -> 2229.81 | I32: =C32*$I$23 -> 236.5 | J32: =D32*$J$23 -> 161.26 | K32: =E32*$K$23 -> 24.86 | M32: =B32*$M$23 -> 5202.89 | N32: =C32*$N$23 -> 827.75 | O32: =D32*$O$23 -> 806.3 | P32: =E32*$P$23 -> 74.58 | R32: =B32*$R$23 -> 5946.16 | S32: =C32*$S$23 -> 1064.25 | T32: =D32*$T$23 -> 564.41 | U32: =E32*$U$23 -> 124.3 | W32: =B32*$W$23 -> 1486.54 | X32: =C32*$X$23 -> 236.5 | Y32: =D32*$Y$23 -> 80.63 | Z32: =E32*$Z$23 -> 24.86 | AB32: Thu | AC32: 85
A33: Wing | B33: =B10*$I$3 -> 16247 | C33: =C10*$I$3 -> 2840.2 | D33: =D10*$I$3 -> 2274.8 | E33: =E10*$I$3 -> 231 | F33: 130 | H33: =B33*$H$23 -> 2437.05 | I33: =C33*$I$23 -> 284.02 | J33: =D33*$J$23 -> 227.48 | K33: =E33*$K$23 -> 23.1 | M33: =B33*$M$23 -> 5686.45 | N33: =C33*$N$23 -> 994.07 | O33: =D33*$O$23 -> 1137.4 | P33: =E33*$P$23 -> 69.3 | R33: =B33*$R$23 -> 6498.8 | S33: =C33*$S$23 -> 1278.09 | T33: =D33*$T$23 -> 796.18 | U33: =E33*$U$23 -> 115.5 | W33: =B33*$W$23 -> 1624.7 | X33: =C33*$X$23 -> 284.02 | Y33: =D33*$Y$23 -> 113.74 | Z33: =E33*$Z$23 -> 23.1 | AB33: Sat | AC33: 60
A34: Fullback | B34: =B11*$I$3 -> 15686 | C34: =C11*$I$3 -> 2409 | D34: =D11*$I$3 -> 1773.2 | E34: =E11*$I$3 -> 204.6 | F34: 121 | H34: =B34*$H$23 -> 2352.9 | I34: =C34*$I$23 -> 240.9 | J34: =D34*$J$23 -> 177.32 | K34: =E34*$K$23 -> 20.46 | M34: =B34*$M$23 -> 5490.1 | N34: =C34*$N$23 -> 843.15 | O34: =D34*$O$23 -> 886.6 | P34: =E34*$P$23 -> 61.38 | R34: =B34*$R$23 -> 6274.4 | S34: =C34*$S$23 -> 1084.05 | T34: =D34*$T$23 -> 620.62 | U34: =E34*$U$23 -> 102.3 | W34: =B34*$W$23 -> 1568.6 | X34: =C34*$X$23 -> 240.9 | Y34: =D34*$Y$23 -> 88.66 | Z34: =E34*$Z$23 -> 20.46 | AC34: =SUM(AC30:AC33) -> 270
H35: 0.1 | I35: 0.1 | J35: 0.1 | K35: 0.1 | M35: 0.3 | N35: 0.3 | O35: 0.3 | P35: 0.25 | R35: 0.3 | S35: 0.35 | T35: 0.4 | U35: 0.35 | W35: 0.3 | X35: 0.25 | Y35: 0.2 | Z35: 0.3 | AB35: Week 5 TOF
A36: Week 3 | H36: Monday - Skills | M36: Tuesday - Team | R36: Thursday - Team | W36: Saturday - Team | AB36: Mon | AC36: 60
A37: Position | B37: TD | C37: HMLD | D37: HSR | E37: A+D | F37: BIP m/min | H37: TD | I37: HMLD | J37: HSR | K37: A+D | M37: TD | N37: HMLD | O37: HSR | P37: A+D | R37: TD | S37: HMLD | T37: HSR | U37: A+D | W37: TD | X37: HMLD | Y37: HSR | Z37: A+D | AB37: Tue | AC37: 85
A38: Prop | B38: =B3*$J$3 -> 14627.6 | C38: =C3*$J$3 -> 1016.6 | D38: =D3*$J$3 -> 260 | E38: =E3*$J$3 -> 80.6 | F38: 85 | H38: =B38*$H$35 -> 1462.76 | I38: =C38*$I$35 -> 101.66 | J38: =D38*$J$35 -> 26 | K38: =E38*$K$35 -> 8.06 | M38: =B38*$M$35 -> 4388.28 | N38: =C38*$N$35 -> 304.98 | O38: =D38*$O$35 -> 78 | P38: =E38*$P$35 -> 20.15 | R38: =B38*$R$35 -> 4388.28 | S38: =C38*$S$35 -> 355.81 | T38: =D38*$T$35 -> 104 | U38: =E38*$U$35 -> 28.21 | W38: =B38*$W$35 -> 4388.28 | X38: =C38*$X$35 -> 254.15 | Y38: =D38*$Y$35 -> 52 | Z38: =E38*$Z$35 -> 24.18 | AB38: Thu | AC38: 90
A39: Hooker | B39: =B4*$J$3 -> 14266.2 | C39: =C4*$J$3 -> 946.4 | D39: =D4*$J$3 -> 364 | E39: =E4*$J$3 -> 78 | F39: 81 | H39: =B39*$H$35 -> 1426.62 | I39: =C39*$I$35 -> 94.64 | J39: =D39*$J$35 -> 36.4 | K39: =E39*$K$35 -> 7.8 | M39: =B39*$M$35 -> 4279.86 | N39: =C39*$N$35 -> 283.92 | O39: =D39*$O$35 -> 109.2 | P39: =E39*$P$35 -> 19.5 | R39: =B39*$R$35 -> 4279.86 | S39: =C39*$S$35 -> 331.24 | T39: =D39*$T$35 -> 145.6 | U39: =E39*$U$35 -> 27.3 | W39: =B39*$W$35 -> 4279.86 | X39: =C39*$X$35 -> 236.6 | Y39: =D39*$Y$35 -> 72.8 | Z39: =E39*$Z$35 -> 23.4 | AB39: Sat | AC39: 70
A40: Lock | B40: =B5*$J$3 -> 16403.4 | C40: =C5*$J$3 -> 1463.8 | D40: =D5*$J$3 -> 738.4 | E40: =E5*$J$3 -> 137.8 | F40: 103 | H40: =B40*$H$35 -> 1640.34 | I40: =C40*$I$35 -> 146.38 | J40: =D40*$J$35 -> 73.84 | K40: =E40*$K$35 -> 13.78 | M40: =B40*$M$35 -> 4921.02 | N40: =C40*$N$35 -> 439.14 | O40: =D40*$O$35 -> 221.52 | P40: =E40*$P$35 -> 34.45 | R40: =B40*$R$35 -> 4921.02 | S40: =C40*$S$35 -> 512.33 | T40: =D40*$T$35 -> 295.36 | U40: =E40*$U$35 -> 48.23 | W40: =B40*$W$35 -> 4921.02 | X40: =C40*$X$35 -> 365.95 | Y40: =D40*$Y$35 -> 147.68 | Z40: =E40*$Z$35 -> 41.34 | AC40: =SUM(AC36:AC39) -> 305
...

Sheet In-Season Load
B1: Target Match Load | H1: Weekly Progressions - In-Season Peaking Plan
A2: Position | B2: TD | C2: HMLD | D2: HSR | E2: A+D | F2: BIP m/min
A3: Prop | B3: ='Pre-Season Load'!B3 -> 5626 | C3: ='Pre-Season Load'!C3 -> 391 | D3: ='Pre-Season Load'!D3 -> 100 | E3: ='Pre-Season Load'!E3 -> 31 | F3: ='Pre-Season Load'!F3 -> 85 | G3: Week | H3: Dates | I3: Saturday | J3: Focus | K3: Load Scalar | L3: Avg TD | M3: Avg HMLD | N3: Avg HSR | O3: Avg A+D | P3: Weekly TOF | Q3: Weekly Total (x Match)
A4: Hooker | B4: ='Pre-Season Load'!B4 -> 5487 | C4: ='Pre-Season Load'!C4 -> 364 | D4: ='Pre-Season Load'!D4 -> 140 | E4: ='Pre-Season Load'!E4 -> 30 | F4: ='Pre-Season Load'!F4 -> 81 | G4: Week 1 | H4: 9/21 - 9/27 | I4: 46291 | J4: Normal load | K4: 1 | L4: =AVERAGE(B22:B30) -> 16969.717 | M4: =AVERAGE(C22:C30) -> 2158.5722 | N4: =AVERAGE(D22:D30) -> 1291.6622 | O4: =AVERAGE(E22:E30) -> 227.57222 | P4: =AR27 -> 300 | Q4: =L4/AVERAGE($B$3:$B$11) -> 2.65
A5: Lock | B5: ='Pre-Season Load'!B5 -> 6309 | C5: ='Pre-Season Load'!C5 -> 563 | D5: ='Pre-Season Load'!D5 -> 284 | E5: ='Pre-Season Load'!E5 -> 53 | F5: ='Pre-Season Load'!F5 -> 103 | G5: Week 2 | H5: 9/28 - 10/4 | I5: 46298 | J5: Normal load | K5: 0.96 | L5: =AVERAGE(B34:B42) -> 16547.075 | M5: =AVERAGE(C34:C42) -> 2104.8116 | N5: =AVERAGE(D34:D42) -> 1260.178 | O5: =AVERAGE(E34:E42) -> 221.51378 | P5: =AR39 -> 300 | Q5: =L5/AVERAGE($B$3:$B$11) -> 2.584
A6: Back row | B6: ='Pre-Season Load'!B6 -> 6399 | C6: ='Pre-Season Load'!C6 -> 698 | D6: ='Pre-Season Load'!D6 -> 356 | E6: ='Pre-Season Load'!E6 -> 71 | F6: ='Pre-Season Load'!F6 -> 106 | G6: Week 3 | H6: 10/5 - 10/11 | I6: 46305 | J6: PEAK - taper | K6: 1 | L6: =AVERAGE(B46:B54) -> 14728.433 | M6: =AVERAGE(C46:C54) -> 1873.4778 | N6: =AVERAGE(D46:D54) -> 1130.2044 | O6: =AVERAGE(E46:E54) -> 192.56111 | P6: =AR51 -> 265 | Q6: =L6/AVERAGE($B$3:$B$11) -> 2.3
A7: Scrum-half | B7: ='Pre-Season Load'!B7 -> 6484 | C7: ='Pre-Season Load'!C7 -> 1193 | D7: ='Pre-Season Load'!D7 -> 819 | E7: ='Pre-Season Load'!E7 -> 102 | F7: ='Pre-Season Load'!F7 -> 106 | G7: Week 4 | H7: 10/12 - 10/18 | I7: 46312 | J7: Reload | K7: 1 | L7: =AVERAGE(B58:B66) -> 16969.717 | M7: =AVERAGE(C58:C66) -> 2158.5722 | N7: =AVERAGE(D58:D66) -> 1291.6622 | O7: =AVERAGE(E58:E66) -> 227.57222 | P7: =AR63 -> 300 | Q7: =L7/AVERAGE($B$3:$B$11) -> 2.65
A8: Fly-half | B8: ='Pre-Season Load'!B8 -> 6056 | C8: ='Pre-Season Load'!C8 -> 661 | D8: ='Pre-Season Load'!D8 -> 269 | E8: ='Pre-Season Load'!E8 -> 87 | F8: ='Pre-Season Load'!F8 -> 95 | G8: Week 5 | H8: 10/19 - 10/25 | I8: BYE | J8: DELOAD - recovery | K8: 1 | L8: =AVERAGE(B70:B78) -> 8452.84 | M8: =AVERAGE(C70:C78) -> 1107.7956 | N8: =AVERAGE(D70:D78) -> 655.92222 | O8: =AVERAGE(E70:E78) -> 120.25556 | P8: =AR75 -> 175 | Q8: =L8/AVERAGE($B$3:$B$11) -> 1.32
A9: Center | B9: ='Pre-Season Load'!B9 -> 6757 | C9: ='Pre-Season Load'!C9 -> 1075 | D9: ='Pre-Season Load'!D9 -> 733 | E9: ='Pre-Season Load'!E9 -> 113 | F9: ='Pre-Season Load'!F9 -> 112 | G9: Week 6 | H9: 10/26 - 11/1 | I9: 46326 | J9: Normal load | K9: 1 | L9: =AVERAGE(B82:B90) -> 16969.717 | M9: =AVERAGE(C82:C90) -> 2158.5722 | N9: =AVERAGE(D82:D90) -> 1291.6622 | O9: =AVERAGE(E82:E90) -> 227.57222 | P9: =AR87 -> 300 | Q9: =L9/AVERAGE($B$3:$B$11) -> 2.65
A10: Wing | B10: ='Pre-Season Load'!B10 -> 7385 | C10: ='Pre-Season Load'!C10 -> 1291 | D10: ='Pre-Season Load'!D10 -> 1034 | E10: ='Pre-Season Load'!E10 -> 105 | F10: ='Pre-Season Load'!F10 -> 130 | G10: Week 7 | H10: 11/2 - 11/8 | I10: 46333 | J10: Pre-taper | K10: 0.93 | L10: =AVERAGE(B94:B102) -> 16230.093 | M10: =AVERAGE(C94:C102) -> 2064.4911 | N10: =AVERAGE(D94:D102) -> 1236.5648 | O10: =AVERAGE(E94:E102) -> 216.96994 | P10: =AR99 -> 300 | Q10: =L10/AVERAGE($B$3:$B$11) -> 2.5345
A11: Fullback | B11: ='Pre-Season Load'!B11 -> 7130 | C11: ='Pre-Season Load'!C11 -> 1095 | D11: ='Pre-Season Load'!D11 -> 806 | E11: ='Pre-Season Load'!E11 -> 93 | F11: ='Pre-Season Load'!F11 -> 121 | G11: Week 8 | H11: 11/9 - 11/15 | I11: 46340 | J11: PEAK - taper | K11: 1 | L11: =AVERAGE(B106:B114) -> 14728.433 | M11: =AVERAGE(C106:C114) -> 1873.4778 | N11: =AVERAGE(D106:D114) -> 1130.2044 | O11: =AVERAGE(E106:E114) -> 192.56111 | P11: =AR111 -> 265 | Q11: =L11/AVERAGE($B$3:$B$11) -> 2.3
G12: Week 9 | H12: 11/16 - 11/22 | I12: 46347 | J12: Reload | K12: 0.97 | L12: =AVERAGE(B118:B126) -> 16652.735 | M12: =AVERAGE(C118:C126) -> 2118.2517 | N12: =AVERAGE(D118:D126) -> 1268.049 | O12: =AVERAGE(E118:E126) -> 223.02839 | P12: =AR123 -> 300 | Q12: =L12/AVERAGE($B$3:$B$11) -> 2.6005
G13: Week 10 | H13: 11/23 - 11/29 | I13: OFF | J13: DELOAD - Thanksgiving | K13: 1 | L13: =AVERAGE(B130:B138) -> 8837.06 | M13: =AVERAGE(C130:C138) -> 1172.96 | N13: =AVERAGE(D130:D138) -> 691.24111 | O13: =AVERAGE(E130:E138) -> 129.38889 | P13: =AR135 -> 185 | Q13: =L13/AVERAGE($B$3:$B$11) -> 1.38
G14: Week 11 | H14: 11/30 - 12/6 | I14: 46361 | J14: PEAK - taper | K14: 1 | L14: =AVERAGE(B142:B150) -> 14728.433 | M14: =AVERAGE(C142:C150) -> 1873.4778 | N14: =AVERAGE(D142:D150) -> 1130.2044 | O14: =AVERAGE(E142:E150) -> 192.56111 | P14: =AR147 -> 265 | Q14: =L14/AVERAGE($B$3:$B$11) -> 2.3
A16: Session % = share of MATCH load (see note). Weekly total is the sum of the 7 sessions.
H19: 0.22 | I19: 0.18 | J19: 0.15 | K19: 0.2 | M19: 0.25 | N19: 0.28 | O19: 0.35 | P19: 0.4 | R19: 0.42 | S19: 0.45 | T19: 0.38 | U19: 0.5 | W19: 0.2 | X19: 0.22 | Y19: 0.28 | Z19: 0.32 | AB19: 0.38 | AC19: 0.4 | AD19: 0.32 | AE19: 0.45 | AG19: 0.18 | AH19: 0.12 | AI19: 0.08 | AJ19: 0.12 | AL19: 1 | AM19: 1 | AN19: 1 | AO19: 1 | AQ19: Week 1 TOF (min)
A20: Week 1 | 9/21 - 9/27 | Match 9/26 | H20: Monday - Light Training | M20: Tuesday AM - Units | R20: Tuesday PM - Team | W20: Thursday AM - Units | AB20: Thursday PM - Team | AG20: Friday - Captain's Run | AL20: Saturday - MATCH (9/26) | AQ20: Mon | AR20: 30
A21: Position | B21: TD | C21: HMLD | D21: HSR | E21: A+D | F21: BIP m/min | H21: TD | I21: HMLD | J21: HSR | K21: A+D | M21: TD | N21: HMLD | O21: HSR | P21: A+D | R21: TD | S21: HMLD | T21: HSR | U21: A+D | W21: TD | X21: HMLD | Y21: HSR | Z21: A+D | AB21: TD | AC21: HMLD | AD21: HSR | AE21: A+D | AG21: TD | AH21: HMLD | AI21: HSR | AJ21: A+D | AL21: TD | AM21: HMLD | AN21: HSR | AO21: A+D | AQ21: Tue AM | AR21: 30
A22: Prop | B22: =H22+M22+R22+W22+AB22+AG22+AL22 -> 14908.9 | C22: =I22+N22+S22+X22+AC22+AH22+AM22 -> 1036.15 | D22: =J22+O22+T22+Y22+AD22+AI22+AN22 -> 256 | E22: =K22+P22+U22+Z22+AE22+AJ22+AO22 -> 92.69 | F22: =F3 -> 85 | H22: =B3*H$19*$K$4 -> 1237.72 | I22: =C3*I$19*$K$4 -> 70.38 | J22: =D3*J$19*$K$4 -> 15 | K22: =E3*K$19*$K$4 -> 6.2 | M22: =B3*M$19*$K$4 -> 1406.5 | N22: =C3*N$19*$K$4 -> 109.48 | O22: =D3*O$19*$K$4 -> 35 | P22: =E3*P$19*$K$4 -> 12.4 | R22: =B3*R$19*$K$4 -> 2362.92 | S22: =C3*S$19*$K$4 -> 175.95 | T22: =D3*T$19*$K$4 -> 38 | U22: =E3*U$19*$K$4 -> 15.5 | W22: =B3*W$19*$K$4 -> 1125.2 | X22: =C3*X$19*$K$4 -> 86.02 | Y22: =D3*Y$19*$K$4 -> 28 | Z22: =E3*Z$19*$K$4 -> 9.92 | AB22: =B3*AB$19*$K$4 -> 2137.88 | AC22: =C3*AC$19*$K$4 -> 156.4 | AD22: =D3*AD$19*$K$4 -> 32 | AE22: =E3*AE$19*$K$4 -> 13.95 | AG22: =B3*AG$19*$K$4 -> 1012.68 | AH22: =C3*AH$19*$K$4 -> 46.92 | AI22: =D3*AI$19*$K$4 -> 8 | AJ22: =E3*AJ$19*$K$4 -> 3.72 | AL22: =B3*AL$19 -> 5626 | AM22: =C3*AM$19 -> 391 | AN22: =D3*AN$19 -> 100 | AO22: =E3*AO$19 -> 31 | AQ22: Tue PM | AR22: 60
A23: Hooker | B23: =H23+M23+R23+W23+AB23+AG23+AL23 -> 14540.55 | C23: =I23+N23+S23+X23+AC23+AH23+AM23 -> 964.6 | D23: =J23+O23+T23+Y23+AD23+AI23+AN23 -> 358.4 | E23: =K23+P23+U23+Z23+AE23+AJ23+AO23 -> 89.7 | F23: =F4 -> 81 | H23: =B4*H$19*$K$4 -> 1207.14 | I23: =C4*I$19*$K$4 -> 65.52 | J23: =D4*J$19*$K$4 -> 21 | K23: =E4*K$19*$K$4 -> 6 | M23: =B4*M$19*$K$4 -> 1371.75 | N23: =C4*N$19*$K$4 -> 101.92 | O23: =D4*O$19*$K$4 -> 49 | P23: =E4*P$19*$K$4 -> 12 | R23: =B4*R$19*$K$4 -> 2304.54 | S23: =C4*S$19*$K$4 -> 163.8 | T23: =D4*T$19*$K$4 -> 53.2 | U23: =E4*U$19*$K$4 -> 15 | W23: =B4*W$19*$K$4 -> 1097.4 | X23: =C4*X$19*$K$4 -> 80.08 | Y23: =D4*Y$19*$K$4 -> 39.2 | Z23: =E4*Z$19*$K$4 -> 9.6 | AB23: =B4*AB$19*$K$4 -> 2085.06 | AC23: =C4*AC$19*$K$4 -> 145.6 | AD23: =D4*AD$19*$K$4 -> 44.8 | AE23: =E4*AE$19*$K$4 -> 13.5 | AG23: =B4*AG$19*$K$4 -> 987.66 | AH23: =C4*AH$19*$K$4 -> 43.68 | AI23: =D4*AI$19*$K$4 -> 11.2 | AJ23: =E4*AJ$19*$K$4 -> 3.6 | AL23: =B4*AL$19 -> 5487 | AM23: =C4*AM$19 -> 364 | AN23: =D4*AN$19 -> 140 | AO23: =E4*AO$19 -> 30 | AQ23: Thu AM | AR23: 25
A24: Lock | B24: =H24+M24+R24+W24+AB24+AG24+AL24 -> 16718.85 | C24: =I24+N24+S24+X24+AC24+AH24+AM24 -> 1491.95 | D24: =J24+O24+T24+Y24+AD24+AI24+AN24 -> 727.04 | E24: =K24+P24+U24+Z24+AE24+AJ24+AO24 -> 158.47 | F24: =F5 -> 103 | H24: =B5*H$19*$K$4 -> 1387.98 | I24: =C5*I$19*$K$4 -> 101.34 | J24: =D5*J$19*$K$4 -> 42.6 | K24: =E5*K$19*$K$4 -> 10.6 | M24: =B5*M$19*$K$4 -> 1577.25 | N24: =C5*N$19*$K$4 -> 157.64 | O24: =D5*O$19*$K$4 -> 99.4 | P24: =E5*P$19*$K$4 -> 21.2 | R24: =B5*R$19*$K$4 -> 2649.78 | S24: =C5*S$19*$K$4 -> 253.35 | T24: =D5*T$19*$K$4 -> 107.92 | U24: =E5*U$19*$K$4 -> 26.5 | W24: =B5*W$19*$K$4 -> 1261.8 | X24: =C5*X$19*$K$4 -> 123.86 | Y24: =D5*Y$19*$K$4 -> 79.52 | Z24: =E5*Z$19*$K$4 -> 16.96 | AB24: =B5*AB$19*$K$4 -> 2397.42 | AC24: =C5*AC$19*$K$4 -> 225.2 | AD24: =D5*AD$19*$K$4 -> 90.88 | AE24: =E5*AE$19*$K$4 -> 23.85 | AG24: =B5*AG$19*$K$4 -> 1135.62 | AH24: =C5*AH$19*$K$4 -> 67.56 | AI24: =D5*AI$19*$K$4 -> 22.72 | AJ24: =E5*AJ$19*$K$4 -> 6.36 | AL24: =B5*AL$19 -> 6309 | AM24: =C5*AM$19 -> 563 | AN24: =D5*AN$19 -> 284 | AO24: =E5*AO$19 -> 53 | AQ24: Thu PM | AR24: 55
A25: Back row | B25: =H25+M25+R25+W25+AB25+AG25+AL25 -> 16957.35 | C25: =I25+N25+S25+X25+AC25+AH25+AM25 -> 1849.7 | D25: =J25+O25+T25+Y25+AD25+AI25+AN25 -> 911.36 | E25: =K25+P25+U25+Z25+AE25+AJ25+AO25 -> 212.29 | F25: =F6 -> 106 | H25: =B6*H$19*$K$4 -> 1407.78 | I25: =C6*I$19*$K$4 -> 125.64 | J25: =D6*J$19*$K$4 -> 53.4 | K25: =E6*K$19*$K$4 -> 14.2 | M25: =B6*M$19*$K$4 -> 1599.75 | N25: =C6*N$19*$K$4 -> 195.44 | O25: =D6*O$19*$K$4 -> 124.6 | P25: =E6*P$19*$K$4 -> 28.4 | R25: =B6*R$19*$K$4 -> 2687.58 | S25: =C6*S$19*$K$4 -> 314.1 | T25: =D6*T$19*$K$4 -> 135.28 | U25: =E6*U$19*$K$4 -> 35.5 | W25: =B6*W$19*$K$4 -> 1279.8 | X25: =C6*X$19*$K$4 -> 153.56 | Y25: =D6*Y$19*$K$4 -> 99.68 | Z25: =E6*Z$19*$K$4 -> 22.72 | AB25: =B6*AB$19*$K$4 -> 2431.62 | AC25: =C6*AC$19*$K$4 -> 279.2 | AD25: =D6*AD$19*$K$4 -> 113.92 | AE25: =E6*AE$19*$K$4 -> 31.95 | AG25: =B6*AG$19*$K$4 -> 1151.82 | AH25: =C6*AH$19*$K$4 -> 83.76 | AI25: =D6*AI$19*$K$4 -> 28.48 | AJ25: =E6*AJ$19*$K$4 -> 8.52 | AL25: =B6*AL$19 -> 6399 | AM25: =C6*AM$19 -> 698 | AN25: =D6*AN$19 -> 356 | AO25: =E6*AO$19 -> 71 | AQ25: Fri | AR25: 20
A26: Scrum-half | B26: =H26+M26+R26+W26+AB26+AG26+AL26 -> 17182.6 | C26: =I26+N26+S26+X26+AC26+AH26+AM26 -> 3161.45 | D26: =J26+O26+T26+Y26+AD26+AI26+AN26 -> 2096.64 | E26: =K26+P26+U26+Z26+AE26+AJ26+AO26 -> 304.98 | F26: =F7 -> 106 | H26: =B7*H$19*$K$4 -> 1426.48 | I26: =C7*I$19*$K$4 -> 214.74 | J26: =D7*J$19*$K$4 -> 122.85 | K26: =E7*K$19*$K$4 -> 20.4 | M26: =B7*M$19*$K$4 -> 1621 | N26: =C7*N$19*$K$4 -> 334.04 | O26: =D7*O$19*$K$4 -> 286.65 | P26: =E7*P$19*$K$4 -> 40.8 | R26: =B7*R$19*$K$4 -> 2723.28 | S26: =C7*S$19*$K$4 -> 536.85 | T26: =D7*T$19*$K$4 -> 311.22 | U26: =E7*U$19*$K$4 -> 51 | W26: =B7*W$19*$K$4 -> 1296.8 | X26: =C7*X$19*$K$4 -> 262.46 | Y26: =D7*Y$19*$K$4 -> 229.32 | Z26: =E7*Z$19*$K$4 -> 32.64 | AB26: =B7*AB$19*$K$4 -> 2463.92 | AC26: =C7*AC$19*$K$4 -> 477.2 | AD26: =D7*AD$19*$K$4 -> 262.08 | AE26: =E7*AE$19*$K$4 -> 45.9 | AG26: =B7*AG$19*$K$4 -> 1167.12 | AH26: =C7*AH$19*$K$4 -> 143.16 | AI26: =D7*AI$19*$K$4 -> 65.52 | AJ26: =E7*AJ$19*$K$4 -> 12.24 | AL26: =B7*AL$19 -> 6484 | AM26: =C7*AM$19 -> 1193 | AN26: =D7*AN$19 -> 819 | AO26: =E7*AO$19 -> 102 | AQ26: Sat | AR26: 80
A27: Fly-half | B27: =H27+M27+R27+W27+AB27+AG27+AL27 -> 16048.4 | C27: =I27+N27+S27+X27+AC27+AH27+AM27 -> 1751.65 | D27: =J27+O27+T27+Y27+AD27+AI27+AN27 -> 688.64 | E27: =K27+P27+U27+Z27+AE27+AJ27+AO27 -> 260.13 | F27: =F8 -> 95 | H27: =B8*H$19*$K$4 -> 1332.32 | I27: =C8*I$19*$K$4 -> 118.98 | J27: =D8*J$19*$K$4 -> 40.35 | K27: =E8*K$19*$K$4 -> 17.4 | M27: =B8*M$19*$K$4 -> 1514 | N27: =C8*N$19*$K$4 -> 185.08 | O27: =D8*O$19*$K$4 -> 94.15 | P27: =E8*P$19*$K$4 -> 34.8 | R27: =B8*R$19*$K$4 -> 2543.52 | S27: =C8*S$19*$K$4 -> 297.45 | T27: =D8*T$19*$K$4 -> 102.22 | U27: =E8*U$19*$K$4 -> 43.5 | W27: =B8*W$19*$K$4 -> 1211.2 | X27: =C8*X$19*$K$4 -> 145.42 | Y27: =D8*Y$19*$K$4 -> 75.32 | Z27: =E8*Z$19*$K$4 -> 27.84 | AB27: =B8*AB$19*$K$4 -> 2301.28 | AC27: =C8*AC$19*$K$4 -> 264.4 | AD27: =D8*AD$19*$K$4 -> 86.08 | AE27: =E8*AE$19*$K$4 -> 39.15 | AG27: =B8*AG$19*$K$4 -> 1090.08 | AH27: =C8*AH$19*$K$4 -> 79.32 | AI27: =D8*AI$19*$K$4 -> 21.52 | AJ27: =E8*AJ$19*$K$4 -> 10.44 | AL27: =B8*AL$19 -> 6056 | AM27: =C8*AM$19 -> 661 | AN27: =D8*AN$19 -> 269 | AO27: =E8*AO$19 -> 87 | AQ27: Total | AR27: =SUM(AR20:AR26) -> 300
A28: Center | B28: =H28+M28+R28+W28+AB28+AG28+AL28 -> 17906.05 | C28: =I28+N28+S28+X28+AC28+AH28+AM28 -> 2848.75 | D28: =J28+O28+T28+Y28+AD28+AI28+AN28 -> 1876.48 | E28: =K28+P28+U28+Z28+AE28+AJ28+AO28 -> 337.87 | F28: =F9 -> 112 | H28: =B9*H$19*$K$4 -> 1486.54 | I28: =C9*I$19*$K$4 -> 193.5 | J28: =D9*J$19*$K$4 -> 109.95 | K28: =E9*K$19*$K$4 -> 22.6 | M28: =B9*M$19*$K$4 -> 1689.25 | N28: =C9*N$19*$K$4 -> 301 | O28: =D9*O$19*$K$4 -> 256.55 | P28: =E9*P$19*$K$4 -> 45.2 | R28: =B9*R$19*$K$4 -> 2837.94 | S28: =C9*S$19*$K$4 -> 483.75 | T28: =D9*T$19*$K$4 -> 278.54 | U28: =E9*U$19*$K$4 -> 56.5 | W28: =B9*W$19*$K$4 -> 1351.4 | X28: =C9*X$19*$K$4 -> 236.5 | Y28: =D9*Y$19*$K$4 -> 205.24 | Z28: =E9*Z$19*$K$4 -> 36.16 | AB28: =B9*AB$19*$K$4 -> 2567.66 | AC28: =C9*AC$19*$K$4 -> 430 | AD28: =D9*AD$19*$K$4 -> 234.56 | AE28: =E9*AE$19*$K$4 -> 50.85 | AG28: =B9*AG$19*$K$4 -> 1216.26 | AH28: =C9*AH$19*$K$4 -> 129 | AI28: =D9*AI$19*$K$4 -> 58.64 | AJ28: =E9*AJ$19*$K$4 -> 13.56 | AL28: =B9*AL$19 -> 6757 | AM28: =C9*AM$19 -> 1075 | AN28: =D9*AN$19 -> 733 | AO28: =E9*AO$19 -> 113
A29: Wing | B29: =H29+M29+R29+W29+AB29+AG29+AL29 -> 19570.25 | C29: =I29+N29+S29+X29+AC29+AH29+AM29 -> 3421.15 | D29: =J29+O29+T29+Y29+AD29+AI29+AN29 -> 2647.04 | E29: =K29+P29+U29+Z29+AE29+AJ29+AO29 -> 313.95 | F29: =F10 -> 130 | H29: =B10*H$19*$K$4 -> 1624.7 | I29: =C10*I$19*$K$4 -> 232.38 | J29: =D10*J$19*$K$4 -> 155.1 | K29: =E10*K$19*$K$4 -> 21 | M29: =B10*M$19*$K$4 -> 1846.25 | N29: =C10*N$19*$K$4 -> 361.48 | O29: =D10*O$19*$K$4 -> 361.9 | P29: =E10*P$19*$K$4 -> 42 | R29: =B10*R$19*$K$4 -> 3101.7 | S29: =C10*S$19*$K$4 -> 580.95 | T29: =D10*T$19*$K$4 -> 392.92 | U29: =E10*U$19*$K$4 -> 52.5 | W29: =B10*W$19*$K$4 -> 1477 | X29: =C10*X$19*$K$4 -> 284.02 | Y29: =D10*Y$19*$K$4 -> 289.52 | Z29: =E10*Z$19*$K$4 -> 33.6 | AB29: =B10*AB$19*$K$4 -> 2806.3 | AC29: =C10*AC$19*$K$4 -> 516.4 | AD29: =D10*AD$19*$K$4 -> 330.88 | AE29: =E10*AE$19*$K$4 -> 47.25 | AG29: =B10*AG$19*$K$4 -> 1329.3 | AH29: =C10*AH$19*$K$4 -> 154.92 | AI29: =D10*AI$19*$K$4 -> 82.72 | AJ29: =E10*AJ$19*$K$4 -> 12.6 | AL29: =B10*AL$19 -> 7385 | AM29: =C10*AM$19 -> 1291 | AN29: =D10*AN$19 -> 1034 | AO29: =E10*AO$19 -> 105
A30: Fullback | B30: =H30+M30+R30+W30+AB30+AG30+AL30 -> 18894.5 | C30: =I30+N30+S30+X30+AC30+AH30+AM30 -> 2901.75 | D30: =J30+O30+T30+Y30+AD30+AI30+AN30 -> 2063.36 | E30: =K30+P30+U30+Z30+AE30+AJ30+AO30 -> 278.07 | F30: =F11 -> 121 | H30: =B11*H$19*$K$4 -> 1568.6 | I30: =C11*I$19*$K$4 -> 197.1 | J30: =D11*J$19*$K$4 -> 120.9 | K30: =E11*K$19*$K$4 -> 18.6 | M30: =B11*M$19*$K$4 -> 1782.5 | N30: =C11*N$19*$K$4 -> 306.6 | O30: =D11*O$19*$K$4 -> 282.1 | P30: =E11*P$19*$K$4 -> 37.2 | R30: =B11*R$19*$K$4 -> 2994.6 | S30: =C11*S$19*$K$4 -> 492.75 | T30: =D11*T$19*$K$4 -> 306.28 | U30: =E11*U$19*$K$4 -> 46.5 | W30: =B11*W$19*$K$4 -> 1426 | X30: =C11*X$19*$K$4 -> 240.9 | Y30: =D11*Y$19*$K$4 -> 225.68 | Z30: =E11*Z$19*$K$4 -> 29.76 | AB30: =B11*AB$19*$K$4 -> 2709.4 | AC30: =C11*AC$19*$K$4 -> 438 | AD30: =D11*AD$19*$K$4 -> 257.92 | AE30: =E11*AE$19*$K$4 -> 41.85 | AG30: =B11*AG$19*$K$4 -> 1283.4 | AH30: =C11*AH$19*$K$4 -> 131.4 | AI30: =D11*AI$19*$K$4 -> 64.48 | AJ30: =E11*AJ$19*$K$4 -> 11.16 | AL30: =B11*AL$19 -> 7130 | AM30: =C11*AM$19 -> 1095 | AN30: =D11*AN$19 -> 806 | AO30: =E11*AO$19 -> 93
H31: 0.22 | I31: 0.18 | J31: 0.15 | K31: 0.2 | M31: 0.25 | N31: 0.28 | O31: 0.35 | P31: 0.4 | R31: 0.42 | S31: 0.45 | T31: 0.38 | U31: 0.5 | W31: 0.2 | X31: 0.22 | Y31: 0.28 | Z31: 0.32 | AB31: 0.38 | AC31: 0.4 | AD31: 0.32 | AE31: 0.45 | AG31: 0.18 | AH31: 0.12 | AI31: 0.08 | AJ31: 0.12 | AL31: 1 | AM31: 1 | AN31: 1 | AO31: 1 | AQ31: Week 2 TOF (min)
A32: Week 2 | 9/28 - 10/4 | Match 10/3 | H32: Monday - Light Training | M32: Tuesday AM - Units | R32: Tuesday PM - Team | W32: Thursday AM - Units | AB32: Thursday PM - Team | AG32: Friday - Captain's Run | AL32: Saturday - MATCH (10/3) | AQ32: Mon | AR32: 30
A33: Position | B33: TD | C33: HMLD | D33: HSR | E33: A+D | F33: BIP m/min | H33: TD | I33: HMLD | J33: HSR | K33: A+D | M33: TD | N33: HMLD | O33: HSR | P33: A+D | R33: TD | S33: HMLD | T33: HSR | U33: A+D | W33: TD | X33: HMLD | Y33: HSR | Z33: A+D | AB33: TD | AC33: HMLD | AD33: HSR | AE33: A+D | AG33: TD | AH33: HMLD | AI33: HSR | AJ33: A+D | AL33: TD | AM33: HMLD | AN33: HSR | AO33: A+D | AQ33: Tue AM | AR33: 30
A34: Prop | B34: =H34+M34+R34+W34+AB34+AG34+AL34 -> 14537.584 | C34: =I34+N34+S34+X34+AC34+AH34+AM34 -> 1010.344 | D34: =J34+O34+T34+Y34+AD34+AI34+AN34 -> 249.76 | E34: =K34+P34+U34+Z34+AE34+AJ34+AO34 -> 90.2224 | F34: =F3 -> 85 | H34: =B3*H$31*$K$5 -> 1188.2112 | I34: =C3*I$31*$K$5 -> 67.5648 | J34: =D3*J$31*$K$5 -> 14.4 | K34: =E3*K$31*$K$5 -> 5.952 | M34: =B3*M$31*$K$5 -> 1350.24 | N34: =C3*N$31*$K$5 -> 105.1008 | O34: =D3*O$31*$K$5 -> 33.6 | P34: =E3*P$31*$K$5 -> 11.904 | R34: =B3*R$31*$K$5 -> 2268.4032 | S34: =C3*S$31*$K$5 -> 168.912 | T34: =D3*T$31*$K$5 -> 36.48 | U34: =E3*U$31*$K$5 -> 14.88 | W34: =B3*W$31*$K$5 -> 1080.192 | X34: =C3*X$31*$K$5 -> 82.5792 | Y34: =D3*Y$31*$K$5 -> 26.88 | Z34: =E3*Z$31*$K$5 -> 9.5232 | AB34: =B3*AB$31*$K$5 -> 2052.3648 | AC34: =C3*AC$31*$K$5 -> 150.144 | AD34: =D3*AD$31*$K$5 -> 30.72 | AE34: =E3*AE$31*$K$5 -> 13.392 | AG34: =B3*AG$31*$K$5 -> 972.1728 | AH34: =C3*AH$31*$K$5 -> 45.0432 | AI34: =D3*AI$31*$K$5 -> 7.68 | AJ34: =E3*AJ$31*$K$5 -> 3.5712 | AL34: =B3*AL$31 -> 5626 | AM34: =C3*AM$31 -> 391 | AN34: =D3*AN$31 -> 100 | AO34: =E3*AO$31 -> 31 | AQ34: Tue PM | AR34: 60
A35: Hooker | B35: =H35+M35+R35+W35+AB35+AG35+AL35 -> 14178.408 | C35: =I35+N35+S35+X35+AC35+AH35+AM35 -> 940.576 | D35: =J35+O35+T35+Y35+AD35+AI35+AN35 -> 349.664 | E35: =K35+P35+U35+Z35+AE35+AJ35+AO35 -> 87.312 | F35: =F4 -> 81 | H35: =B4*H$31*$K$5 -> 1158.8544 | I35: =C4*I$31*$K$5 -> 62.8992 | J35: =D4*J$31*$K$5 -> 20.16 | K35: =E4*K$31*$K$5 -> 5.76 | M35: =B4*M$31*$K$5 -> 1316.88 | N35: =C4*N$31*$K$5 -> 97.8432 | O35: =D4*O$31*$K$5 -> 47.04 | P35: =E4*P$31*$K$5 -> 11.52 | R35: =B4*R$31*$K$5 -> 2212.3584 | S35: =C4*S$31*$K$5 -> 157.248 | T35: =D4*T$31*$K$5 -> 51.072 | U35: =E4*U$31*$K$5 -> 14.4 | W35: =B4*W$31*$K$5 -> 1053.504 | X35: =C4*X$31*$K$5 -> 76.8768 | Y35: =D4*Y$31*$K$5 -> 37.632 | Z35: =E4*Z$31*$K$5 -> 9.216 | AB35: =B4*AB$31*$K$5 -> 2001.6576 | AC35: =C4*AC$31*$K$5 -> 139.776 | AD35: =D4*AD$31*$K$5 -> 43.008 | AE35: =E4*AE$31*$K$5 -> 12.96 | AG35: =B4*AG$31*$K$5 -> 948.1536 | AH35: =C4*AH$31*$K$5 -> 41.9328 | AI35: =D4*AI$31*$K$5 -> 10.752 | AJ35: =E4*AJ$31*$K$5 -> 3.456 | AL35: =B4*AL$31 -> 5487 | AM35: =C4*AM$31 -> 364 | AN35: =D4*AN$31 -> 140 | AO35: =E4*AO$31 -> 30 | AQ35: Thu AM | AR35: 25
A36: Lock | B36: =H36+M36+R36+W36+AB36+AG36+AL36 -> 16302.456 | C36: =I36+N36+S36+X36+AC36+AH36+AM36 -> 1454.792 | D36: =J36+O36+T36+Y36+AD36+AI36+AN36 -> 709.3184 | E36: =K36+P36+U36+Z36+AE36+AJ36+AO36 -> 154.2512 | F36: =F5 -> 103 | H36: =B5*H$31*$K$5 -> 1332.4608 | I36: =C5*I$31*$K$5 -> 97.2864 | J36: =D5*J$31*$K$5 -> 40.896 | K36: =E5*K$31*$K$5 -> 10.176 | M36: =B5*M$31*$K$5 -> 1514.16 | N36: =C5*N$31*$K$5 -> 151.3344 | O36: =D5*O$31*$K$5 -> 95.424 | P36: =E5*P$31*$K$5 -> 20.352 | R36: =B5*R$31*$K$5 -> 2543.7888 | S36: =C5*S$31*$K$5 -> 243.216 | T36: =D5*T$31*$K$5 -> 103.6032 | U36: =E5*U$31*$K$5 -> 25.44 | W36: =B5*W$31*$K$5 -> 1211.328 | X36: =C5*X$31*$K$5 -> 118.9056 | Y36: =D5*Y$31*$K$5 -> 76.3392 | Z36: =E5*Z$31*$K$5 -> 16.2816 | AB36: =B5*AB$31*$K$5 -> 2301.5232 | AC36: =C5*AC$31*$K$5 -> 216.192 | AD36: =D5*AD$31*$K$5 -> 87.2448 | AE36: =E5*AE$31*$K$5 -> 22.896 | AG36: =B5*AG$31*$K$5 -> 1090.1952 | AH36: =C5*AH$31*$K$5 -> 64.8576 | AI36: =D5*AI$31*$K$5 -> 21.8112 | AJ36: =E5*AJ$31*$K$5 -> 6.1056 | AL36: =B5*AL$31 -> 6309 | AM36: =C5*AM$31 -> 563 | AN36: =D5*AN$31 -> 284 | AO36: =E5*AO$31 -> 53 | AQ36: Thu PM | AR36: 55
A37: Back row | B37: =H37+M37+R37+W37+AB37+AG37+AL37 -> 16535.016 | C37: =I37+N37+S37+X37+AC37+AH37+AM37 -> 1803.632 | D37: =J37+O37+T37+Y37+AD37+AI37+AN37 -> 889.1456 | E37: =K37+P37+U37+Z37+AE37+AJ37+AO37 -> 206.6384 | F37: =F6 -> 106 | H37: =B6*H$31*$K$5 -> 1351.4688 | I37: =C6*I$31*$K$5 -> 120.6144 | J37: =D6*J$31*$K$5 -> 51.264 | K37: =E6*K$31*$K$5 -> 13.632 | M37: =B6*M$31*$K$5 -> 1535.76 | N37: =C6*N$31*$K$5 -> 187.6224 | O37: =D6*O$31*$K$5 -> 119.616 | P37: =E6*P$31*$K$5 -> 27.264 | R37: =B6*R$31*$K$5 -> 2580.0768 | S37: =C6*S$31*$K$5 -> 301.536 | T37: =D6*T$31*$K$5 -> 129.8688 | U37: =E6*U$31*$K$5 -> 34.08 | W37: =B6*W$31*$K$5 -> 1228.608 | X37: =C6*X$31*$K$5 -> 147.4176 | Y37: =D6*Y$31*$K$5 -> 95.6928 | Z37: =E6*Z$31*$K$5 -> 21.8112 | AB37: =B6*AB$31*$K$5 -> 2334.3552 | AC37: =C6*AC$31*$K$5 -> 268.032 | AD37: =D6*AD$31*$K$5 -> 109.3632 | AE37: =E6*AE$31*$K$5 -> 30.672 | AG37: =B6*AG$31*$K$5 -> 1105.7472 | AH37: =C6*AH$31*$K$5 -> 80.4096 | AI37: =D6*AI$31*$K$5 -> 27.3408 | AJ37: =E6*AJ$31*$K$5 -> 8.1792 | AL37: =B6*AL$31 -> 6399 | AM37: =C6*AM$31 -> 698 | AN37: =D6*AN$31 -> 356 | AO37: =E6*AO$31 -> 71 | AQ37: Fri | AR37: 20
A38: Scrum-half | B38: =H38+M38+R38+W38+AB38+AG38+AL38 -> 16754.656 | C38: =I38+N38+S38+X38+AC38+AH38+AM38 -> 3082.712 | D38: =J38+O38+T38+Y38+AD38+AI38+AN38 -> 2045.5344 | E38: =K38+P38+U38+Z38+AE38+AJ38+AO38 -> 296.8608 | F38: =F7 -> 106 | H38: =B7*H$31*$K$5 -> 1369.4208 | I38: =C7*I$31*$K$5 -> 206.1504 | J38: =D7*J$31*$K$5 -> 117.936 | K38: =E7*K$31*$K$5 -> 19.584 | M38: =B7*M$31*$K$5 -> 1556.16 | N38: =C7*N$31*$K$5 -> 320.6784 | O38: =D7*O$31*$K$5 -> 275.184 | P38: =E7*P$31*$K$5 -> 39.168 | R38: =B7*R$31*$K$5 -> 2614.3488 | S38: =C7*S$31*$K$5 -> 515.376 | T38: =D7*T$31*$K$5 -> 298.7712 | U38: =E7*U$31*$K$5 -> 48.96 | W38: =B7*W$31*$K$5 -> 1244.928 | X38: =C7*X$31*$K$5 -> 251.9616 | Y38: =D7*Y$31*$K$5 -> 220.1472 | Z38: =E7*Z$31*$K$5 -> 31.3344 | AB38: =B7*AB$31*$K$5 -> 2365.3632 | AC38: =C7*AC$31*$K$5 -> 458.112 | AD38: =D7*AD$31*$K$5 -> 251.5968 | AE38: =E7*AE$31*$K$5 -> 44.064 | AG38: =B7*AG$31*$K$5 -> 1120.4352 | AH38: =C7*AH$31*$K$5 -> 137.4336 | AI38: =D7*AI$31*$K$5 -> 62.8992 | AJ38: =E7*AJ$31*$K$5 -> 11.7504 | AL38: =B7*AL$31 -> 6484 | AM38: =C7*AM$31 -> 1193 | AN38: =D7*AN$31 -> 819 | AO38: =E7*AO$31 -> 102 | AQ38: Sat | AR38: 80
A39: Fly-half | B39: =H39+M39+R39+W39+AB39+AG39+AL39 -> 15648.704 | C39: =I39+N39+S39+X39+AC39+AH39+AM39 -> 1708.024 | D39: =J39+O39+T39+Y39+AD39+AI39+AN39 -> 671.8544 | E39: =K39+P39+U39+Z39+AE39+AJ39+AO39 -> 253.2048 | F39: =F8 -> 95 | H39: =B8*H$31*$K$5 -> 1279.0272 | I39: =C8*I$31*$K$5 -> 114.2208 | J39: =D8*J$31*$K$5 -> 38.736 | K39: =E8*K$31*$K$5 -> 16.704 | M39: =B8*M$31*$K$5 -> 1453.44 | N39: =C8*N$31*$K$5 -> 177.6768 | O39: =D8*O$31*$K$5 -> 90.384 | P39: =E8*P$31*$K$5 -> 33.408 | R39: =B8*R$31*$K$5 -> 2441.7792 | S39: =C8*S$31*$K$5 -> 285.552 | T39: =D8*T$31*$K$5 -> 98.1312 | U39: =E8*U$31*$K$5 -> 41.76 | W39: =B8*W$31*$K$5 -> 1162.752 | X39: =C8*X$31*$K$5 -> 139.6032 | Y39: =D8*Y$31*$K$5 -> 72.3072 | Z39: =E8*Z$31*$K$5 -> 26.7264 | AB39: =B8*AB$31*$K$5 -> 2209.2288 | AC39: =C8*AC$31*$K$5 -> 253.824 | AD39: =D8*AD$31*$K$5 -> 82.6368 | AE39: =E8*AE$31*$K$5 -> 37.584 | AG39: =B8*AG$31*$K$5 -> 1046.4768 | AH39: =C8*AH$31*$K$5 -> 76.1472 | AI39: =D8*AI$31*$K$5 -> 20.6592 | AJ39: =E8*AJ$31*$K$5 -> 10.0224 | AL39: =B8*AL$31 -> 6056 | AM39: =C8*AM$31 -> 661 | AN39: =D8*AN$31 -> 269 | AO39: =E8*AO$31 -> 87 | AQ39: Total | AR39: =SUM(AR32:AR38) -> 300
A40: Center | B40: =H40+M40+R40+W40+AB40+AG40+AL40 -> 17460.088 | C40: =I40+N40+S40+X40+AC40+AH40+AM40 -> 2777.8 | D40: =J40+O40+T40+Y40+AD40+AI40+AN40 -> 1830.7408 | E40: =K40+P40+U40+Z40+AE40+AJ40+AO40 -> 328.8752 | F40: =F9 -> 112 | H40: =B9*H$31*$K$5 -> 1427.0784 | I40: =C9*I$31*$K$5 -> 185.76 | J40: =D9*J$31*$K$5 -> 105.552 | K40: =E9*K$31*$K$5 -> 21.696 | M40: =B9*M$31*$K$5 -> 1621.68 | N40: =C9*N$31*$K$5 -> 288.96 | O40: =D9*O$31*$K$5 -> 246.288 | P40: =E9*P$31*$K$5 -> 43.392 | R40: =B9*R$31*$K$5 -> 2724.4224 | S40: =C9*S$31*$K$5 -> 464.4 | T40: =D9*T$31*$K$5 -> 267.3984 | U40: =E9*U$31*$K$5 -> 54.24 | W40: =B9*W$31*$K$5 -> 1297.344 | X40: =C9*X$31*$K$5 -> 227.04 | Y40: =D9*Y$31*$K$5 -> 197.0304 | Z40: =E9*Z$31*$K$5 -> 34.7136 | AB40: =B9*AB$31*$K$5 -> 2464.9536 | AC40: =C9*AC$31*$K$5 -> 412.8 | AD40: =D9*AD$31*$K$5 -> 225.1776 | AE40: =E9*AE$31*$K$5 -> 48.816 | AG40: =B9*AG$31*$K$5 -> 1167.6096 | AH40: =C9*AH$31*$K$5 -> 123.84 | AI40: =D9*AI$31*$K$5 -> 56.2944 | AJ40: =E9*AJ$31*$K$5 -> 13.0176 | AL40: =B9*AL$31 -> 6757 | AM40: =C9*AM$31 -> 1075 | AN40: =D9*AN$31 -> 733 | AO40: =E9*AO$31 -> 113
A41: Wing | B41: =H41+M41+R41+W41+AB41+AG41+AL41 -> 19082.84 | C41: =I41+N41+S41+X41+AC41+AH41+AM41 -> 3335.944 | D41: =J41+O41+T41+Y41+AD41+AI41+AN41 -> 2582.5184 | E41: =K41+P41+U41+Z41+AE41+AJ41+AO41 -> 305.592 | F41: =F10 -> 130 | H41: =B10*H$31*$K$5 -> 1559.712 | I41: =C10*I$31*$K$5 -> 223.0848 | J41: =D10*J$31*$K$5 -> 148.896 | K41: =E10*K$31*$K$5 -> 20.16 | M41: =B10*M$31*$K$5 -> 1772.4 | N41: =C10*N$31*$K$5 -> 347.0208 | O41: =D10*O$31*$K$5 -> 347.424 | P41: =E10*P$31*$K$5 -> 40.32 | R41: =B10*R$31*$K$5 -> 2977.632 | S41: =C10*S$31*$K$5 -> 557.712 | T41: =D10*T$31*$K$5 -> 377.2032 | U41: =E10*U$31*$K$5 -> 50.4 | W41: =B10*W$31*$K$5 -> 1417.92 | X41: =C10*X$31*$K$5 -> 272.6592 | Y41: =D10*Y$31*$K$5 -> 277.9392 | Z41: =E10*Z$31*$K$5 -> 32.256 | AB41: =B10*AB$31*$K$5 -> 2694.048 | AC41: =C10*AC$31*$K$5 -> 495.744 | AD41: =D10*AD$31*$K$5 -> 317.6448 | AE41: =E10*AE$31*$K$5 -> 45.36 | AG41: =B10*AG$31*$K$5 -> 1276.128 | AH41: =C10*AH$31*$K$5 -> 148.7232 | AI41: =D10*AI$31*$K$5 -> 79.4112 | AJ41: =E10*AJ$31*$K$5 -> 12.096 | AL41: =B10*AL$31 -> 7385 | AM41: =C10*AM$31 -> 1291 | AN41: =D10*AN$31 -> 1034 | AO41: =E10*AO$31 -> 105
A42: Fullback | B42: =H42+M42+R42+W42+AB42+AG42+AL42 -> 18423.92 | C42: =I42+N42+S42+X42+AC42+AH42+AM42 -> 2829.48 | D42: =J42+O42+T42+Y42+AD42+AI42+AN42 -> 2013.0656 | E42: =K42+P42+U42+Z42+AE42+AJ42+AO42 -> 270.6672 | F42: =F11 -> 121 | H42: =B11*H$31*$K$5 -> 1505.856 | I42: =C11*I$31*$K$5 -> 189.216 | J42: =D11*J$31*$K$5 -> 116.064 | K42: =E11*K$31*$K$5 -> 17.856 | M42: =B11*M$31*$K$5 -> 1711.2 | N42: =C11*N$31*$K$5 -> 294.336 | O42: =D11*O$31*$K$5 -> 270.816 | P42: =E11*P$31*$K$5 -> 35.712 | R42: =B11*R$31*$K$5 -> 2874.816 | S42: =C11*S$31*$K$5 -> 473.04 | T42: =D11*T$31*$K$5 -> 294.0288 | U42: =E11*U$31*$K$5 -> 44.64 | W42: =B11*W$31*$K$5 -> 1368.96 | X42: =C11*X$31*$K$5 -> 231.264 | Y42: =D11*Y$31*$K$5 -> 216.6528 | Z42: =E11*Z$31*$K$5 -> 28.5696 | AB42: =B11*AB$31*$K$5 -> 2601.024 | AC42: =C11*AC$31*$K$5 -> 420.48 | AD42: =D11*AD$31*$K$5 -> 247.6032 | AE42: =E11*AE$31*$K$5 -> 40.176 | AG42: =B11*AG$31*$K$5 -> 1232.064 | AH42: =C11*AH$31*$K$5 -> 126.144 | AI42: =D11*AI$31*$K$5 -> 61.9008 | AJ42: =E11*AJ$31*$K$5 -> 10.7136 | AL42: =B11*AL$31 -> 7130 | AM42: =C11*AM$31 -> 1095 | AN42: =D11*AN$31 -> 806 | AO42: =E11*AO$31 -> 93
H43: 0.18 | I43: 0.15 | J43: 0.12 | K43: 0.16 | M43: 0.22 | N43: 0.24 | O43: 0.32 | P43: 0.35 | R43: 0.38 | S43: 0.4 | T43: 0.34 | U43: 0.44 | W43: 0.14 | X43: 0.15 | Y43: 0.18 | Z43: 0.2 | AB43: 0.24 | AC43: 0.26 | AD43: 0.2 | AE43: 0.28 | AG43: 0.14 | AH43: 0.1 | AI43: 0.08 | AJ43: 0.1 | AL43: 1 | AM43: 1 | AN43: 1 | AO43: 1 | AQ43: Week 3 TOF (min)
...
